forwarding local port 8000 to external port 80
starting up user application
2024-12-06 05:27:06.664747: W tensorflow/stream_executor/platform/default/dso_loader.cc:64] Could not load dynamic library 'libcudart.so.11.0'; dlerror: libcudart.so.11.0: cannot open shared object file: No such file or directory
[   INFO   ] MusicExtractorSVM: no classifier models were configured by default
2024-12-06 05:27:09.176363: W tensorflow/stream_executor/platform/default/dso_loader.cc:64] Could not load dynamic library 'libcuda.so.1'; dlerror: libcuda.so.1: cannot open shared object file: No such file or directory
2024-12-06 05:27:09.176429: I tensorflow/stream_executor/cuda/cuda_diagnostics.cc:156] kernel driver does not appear to be running on this host (localhost): /proc/driver/nvidia/version does not exist
INFO:     Waiting for application startup.
INFO:     Application startup complete.
    | Traceback (most recent call last):
  File "/home/runner/cbbb1889-2eff-4c42-ab04-5c66cbe9e7af/.pythonlibs/lib/python3.8/site-packages/starlette/_utils.py", line 82, in collapse_excgroups
  |     raise BaseExceptionGroup(
  |   File "/home/runner/cbbb1889-2eff-4c42-ab04-5c66cbe9e7af/.pythonlibs/lib/python3.8/site-packages/starlette/_utils.py", line 76, in collapse_excgroups
    |   File "/home/runner/cbbb1889-2eff-4c42-ab04-5c66cbe9e7af/.pythonlibs/lib/python3.8/site-packages/starlette/_utils.py", line 82, in collapse_excgroups
    |     self.gen.throw(type, value, traceback)

    | Traceback (most recent call last):
    |     response_sent.set()
  |     raise BaseExceptionGroup(
  File "/home/runner/cbbb1889-2eff-4c42-ab04-5c66cbe9e7af/.pythonlibs/lib/python3.8/site-packages/starlette/_utils.py", line 82, in collapse_excgroups
  File "/home/runner/cbbb1889-2eff-4c42-ab04-5c66cbe9e7af/.pythonlibs/lib/python3.8/site-packages/starlette/applications.py", line 113, in __call__
    return await self.app(scope, receive, send)
  |   File "/home/runner/cbbb1889-2eff-4c42-ab04-5c66cbe9e7af/.pythonlibs/lib/python3.8/site-packages/starlette/middleware/base.py", line 189, in __call__
ERROR:    Exception in ASGI application
    |     self.gen.throw(type, value, traceback)
  File "/home/runner/cbbb1889-2eff-4c42-ab04-5c66cbe9e7af/.pythonlibs/lib/python3.8/site-packages/starlette/middleware/errors.py", line 182, in __call__
  |     raise BaseExceptionGroup(
  File "/home/runner/cbbb1889-2eff-4c42-ab04-5c66cbe9e7af/.pythonlibs/lib/python3.8/site-packages/uvicorn/middleware/proxy_headers.py", line 60, in __call__
  File "/home/runner/cbbb1889-2eff-4c42-ab04-5c66cbe9e7af/lab/essentia/main.py", line 34, in verify_rapidapi_proxy
ERROR:    Exception in ASGI application
  |     raise BaseExceptionGroup(
    |   File "/home/runner/cbbb1889-2eff-4c42-ab04-5c66cbe9e7af/.pythonlibs/lib/python3.8/site-packages/starlette/middleware/base.py", line 187, in __call__
INFO:     127.0.0.1:39164 - "GET / HTTP/1.1" 500 Internal Server Error
    |     response = await self.dispatch_func(request, call_next)
    raise exc
2024-12-06T05:28:33Z error: The deployment failed to initialize due to a configuration or code error. Check the logs tab for more information. For additional support, contact us at support@replit.com. 
